Workbook

Sheet SummaryResults
A1: THE VALUE OF INFORMATION: QUEUEING MODEL | F1: RESET (1=Y,0=N) | H1: 0 | J1: THE VALUE OF INFORMATION: QUEUEING MODEL | P1: THE VALUE OF INFORMATION: QUEUEING MODEL | U1: RESET (1=Y,0=N) | W1: 0
A2: Poisson arrival rate (cust/sec) = | D2: 0.667 | F2: ITERATION | H2: 32 | J2: Poisson arrival rate (cust/sec) = | M2: 0.667 | P2: Poisson arrival rate (cust/sec) = | S2: 0.667 | U2: ITERATION | W2: =IF(RESET=1,0,W2+1) -> #N/A
A3: Freeway Service time mean (sec) = | D3: 2 | J3: Freeway Service time mean (sec) = | M3: 2 | P3: Freeway Service time mean (sec) = | S3: 2
A4: Arterial Service time mean (sec) = | D4: 2 | J4: Arterial Service time mean (sec) = | M4: 2 | P4: Arterial Service time mean (sec) = | S4: 2
A5: Freeway Service time range (sec) = | D5: 0.5 | J5: Freeway Service time range (sec) = | M5: 0.5 | P5: Freeway Service time range (sec) = | S5: 0.5
A6: Demand Coefficient = | D6: -0.15 | J6: Demand Coefficient = | M6: -0.15 | P6: Demand Coefficient = | S6: -0.15
A7: Alternate Time (sec) | D7: 0 | J7: Alternate Time (sec) | M7: 0 | P7: Alternate Time (sec) | S7: 0
A8: Percent Informed | D8: 0.95 | J8: Percent Informed | M8: 0.05 | P8: Percent Informed | S8: 0.5
A10: Percent Arterial (RESULT) | D10: 0.515 | J10: Percent Arterial (RESULT) | M10: =AVERAGE(Q18:Q1017) -> #DIV/0! | P10: Percent Arterial (RESULT) | S10: =AVERAGE(W18:W1017) -> #DIV/0!
A11: Percent Informed (RESULT) | D11: 0.954 | J11: Percent Informed (RESULT) | M11: =AVERAGE(K18:K1017) -> #DIV/0! | P11: Percent Informed (RESULT) | S11: =AVERAGE(Q18:Q1017) -> #DIV/0!
A14: RESULTS | C14: CUM TOT. DELAY | D14: CUM N | E14: CUM. AVG. DELAY | J14: RESULTS | L14: CUM TOT. DELAY | M14: CUM N | N14: CUM. AVG. DELAY | P14: RESULTS | R14: CUM TOT. DELAY | S14: CUM N | T14: CUM. AVG. DELAY
A15: TOTAL | B15: FREEWAY | C15: 46754.999 | D15: 15999 | E15: 2.9223701 | J15: TOTAL | K15: FREEWAY | L15: 101121.61 | M15: 30007 | N15: 3.369934 | P15: TOTAL | Q15: FREEWAY | R15: 43824.623 | S15: 13980 | T15: 3.1348085
A16: TOTAL | B16: ARTERIAL | C16: 47114.94 | D16: 16001 | E16: 2.9444997 | J16: TOTAL | K16: ARTERIAL | L16: 101554.54 | M16: 29993 | N16: 3.3859415 | P16: TOTAL | Q16: ARTERIAL | R16: 44113.739 | S16: 14020 | T16: 3.1464864
A17: TOTAL | B17: TOTAL | C17: 93869.939 | D17: 32000 | E17: 2.9334356 | J17: TOTAL | K17: TOTAL | L17: 202676.15 | M17: 60000 | N17: 3.3779359 | P17: TOTAL | Q17: TOTAL | R17: 87938.362 | S17: 28000 | T17: 3.1406558
A18: TOTAL | B18: INFORMED | C18: 88502.128 | D18: 30398 | E18: 2.9114457 | J18: TOTAL | K18: INFORMED | L18: 92489.866 | M18: 31813 | N18: 2.9072978 | P18: TOTAL | Q18: INFORMED | R18: 40217.331 | S18: 14077 | T18: 2.8569532
A19: TOTAL | B19: UNINFORMED | C19: 5367.8115 | D19: 1602 | E19: 3.3506938 | J19: TOTAL | K19: UNINFORMED | L19: 110186.29 | M19: 28187 | N19: 3.9091172 | P19: TOTAL | Q19: UNINFORMED | R19: 47721.032 | S19: 13923 | T19: 3.4274964
A20: FREEWAY | B20: INFORMED | C20: 44041.672 | D20: 15179 | E20: 2.9014871 | J20: FREEWAY | K20: INFORMED | L20: 46121.395 | M20: 15907 | N20: 2.8994402 | P20: FREEWAY | Q20: INFORMED | R20: 20006.981 | S20: 7015 | T20: 2.8520286
A21: FREEWAY | B21: UNINFORMED | C21: 2713.3265 | D21: 820 | E21: 3.3089347 | J21: FREEWAY | K21: UNINFORMED | L21: 55000.214 | M21: 14100 | N21: 3.9007244 | P21: FREEWAY | Q21: UNINFORMED | R21: 23817.643 | S21: 6965 | T21: 3.4196185
A22: ARTERIAL | B22: INFORMED | C22: 44460.455 | D22: 15219 | E22: 2.9213782 | J22: ARTERIAL | K22: INFORMED | L22: 46368.471 | M22: 15906 | N22: 2.915156 | P22: ARTERIAL | Q22: INFORMED | R22: 20210.35 | S22: 7062 | T22: 2.8618451
A23: ARTERIAL | B23: UNINFORMED | C23: 2654.485 | D23: 782 | E23: 3.3944821 | J23: ARTERIAL | K23: UNINFORMED | L23: 55186.072 | M23: 14087 | N23: 3.9175177 | P23: ARTERIAL | Q23: UNINFORMED | R23: 23903.389 | S23: 6958 | T23: 3.4353822
C24: secs. | L24: secs. | R24: secs.

Sheet AVGTI
A1: Average of Time Informed | B1: Percent Informed
A2: Poisson arrival rate | B2: 0 | C2: 0.17 | D2: 0.33 | E2: 0.5 | F2: 0.67 | G2: 0.83 | H2: 1 | I2: Grand Total
A3: 0.5 | B3: =#REF! -> #DIV/0! | C3: 2.3638827 | D3: 2.3869526 | E3: 2.392728 | F3: 2.4089202 | G3: 2.4101214 | H3: 2.4227644 | I3: 2.3975615
A4: 0.67 | B4: =#REF! -> #DIV/0! | C4: 2.8266893 | D4: 2.8721658 | E4: 2.8953663 | F4: 2.9158806 | G4: 2.9286398 | H4: 2.9019804 | I4: 2.8901204
A5: 0.95 | B5: =#REF! -> #DIV/0! | C5: 9.520706 | D5: 9.4800309 | E5: 9.0548647 | F5: 9.8525365 | G5: 9.9854758 | H5: 9.9426239 | I5: 9.639373
A6: 1 | B6: =#REF! -> #DIV/0! | C6: 16.5518 | D6: 20.447163 | E6: 17.693367 | F6: 18.157584 | G6: 18.563641 | H6: 19.279514 | I6: 18.448845
A7: 1.05 | B7: =#REF! -> #DIV/0! | C7: 30.382332 | D7: 33.580609 | E7: 30.840601 | F7: 36.309015 | G7: 36.196519 | H7: 30.045464 | I7: 32.892423
A8: Grand Total | B8: =#REF! -> #DIV/0! | C8: 13.639433 | D8: 15.313443 | E8: 13.950868 | F8: 15.494024 | G8: 15.589021 | H8: 14.300119 | I8: 14.714485
C35: 0.17 | D35: 0.33 | E35: 0.5 | F35: 0.67 | G35: 0.83 | H35: 1
B36: 0.5 | C36: 2.3638827 | D36: 2.3869526 | E36: 2.392728 | F36: 2.4089202 | G36: 2.4101214 | H36: 2.4227644
B37: 0.67 | C37: 2.8266893 | D37: 2.8721658 | E37: 2.8953663 | F37: 2.9158806 | G37: 2.9286398 | H37: 2.9019804
B38: 0.95 | C38: 9.520706 | D38: 9.4800309 | E38: 9.0548647 | F38: 9.8525365 | G38: 9.9854758 | H38: 9.9426239
B39: 1 | C39: 16.5518 | D39: 20.447163 | E39: 17.693367 | F39: 18.157584 | G39: 18.563641 | H39: 19.279514
B40: 1.05 | C40: 30.382332 | D40: 33.580609 | E40: 30.840601 | F40: 36.309015 | G40: 36.196519 | H40: 30.045464

Sheet AVGTU
A1: Average of Time Uninformed | B1: Percent Informed
A2: Poisson arrival rate | B2: 0 | C2: 0.17 | D2: 0.33 | E2: 0.5 | F2: 0.67 | G2: 0.83 | H2: 1 | I2: Grand Total
A3: 0.5 | B3: 2.9974143 | C3: 2.9038331 | D3: 2.8588485 | E3: 2.7986281 | F3: 2.770604 | G3: 2.737312 | H3: =#REF! -> #DIV/0! | I3: 2.84444
A4: 0.67 | B4: 4.0013215 | C4: 3.7071677 | D4: 3.5771693 | E4: 3.4694709 | F4: 3.3751423 | G4: 3.317358 | H4: =#REF! -> #DIV/0! | I4: 3.5746049
A5: 0.95 | B5: 14.932108 | C5: 11.748035 | D5: 10.766159 | E5: 9.9645611 | F5: 10.570638 | G5: 10.661985 | H5: =#REF! -> #DIV/0! | I5: 11.440581
A6: 1 | B6: 26.406196 | C6: 19.177193 | D6: 21.9949 | E6: 18.62121 | F6: 18.889695 | G6: 19.172077 | H6: =#REF! -> #DIV/0! | I6: 20.710212
A7: 1.05 | B7: 38.879091 | C7: 33.380311 | D7: 35.127272 | E7: 31.949706 | F7: 37.058154 | G7: 36.787902 | H7: =#REF! -> #DIV/0! | I7: 35.530406
A8: Grand Total | B8: 19.231393 | C8: 15.606301 | D8: 16.476189 | E8: 14.763626 | F8: 16.11415 | G8: 16.117052 | H8: =#REF! -> #DIV/0! | I8: 16.384785
B36: 0 | C36: 0.17 | D36: 0.33 | E36: 0.5 | F36: 0.67 | G36: 0.83
A37: 0.5 | B37: 2.9974143 | C37: 2.9038331 | D37: 2.8588485 | E37: 2.7986281 | F37: 2.770604 | G37: 2.737312
A38: 0.67 | B38: 4.0013215 | C38: 3.7071677 | D38: 3.5771693 | E38: 3.4694709 | F38: 3.3751423 | G38: 3.317358
A39: 0.95 | B39: 14.932108 | C39: 11.748035 | D39: 10.766159 | E39: 9.9645611 | F39: 10.570638 | G39: 10.661985
A40: 1 | B40: 26.406196 | C40: 19.177193 | D40: 21.9949 | E40: 18.62121 | F40: 18.889695 | G40: 19.172077
A41: 1.05 | B41: 38.879091 | C41: 33.380311 | D41: 35.127272 | E41: 31.949706 | F41: 37.058154 | G41: 36.787902

Sheet AVGTO
A1: Average of Time Overall | B1: Percent Informed
A2: Poisson arrival rate | B2: 0 | C2: 0.17 | D2: 0.33 | E2: 0.5 | F2: 0.67 | G2: 0.83 | H2: 1 | I2: Grand Total
A3: 0.5 | B3: 2.9974143 | C3: 2.8114831 | D3: 2.7034745 | E3: 2.5944321 | F3: 2.528139 | G3: 2.4660736 | H3: 2.4227644 | I3: 2.6462544 | J3: =(B3-H3)/B3 -> 0.19171521
A4: 0.67 | B4: 4.0959772 | C4: 3.5565853 | D4: 3.3446625 | E4: 3.1817646 | F4: 3.068922 | G4: 2.9944611 | H4: 2.9019804 | I4: 3.223216 | J4: =(B4-H4)/B4 -> 0.29150473
A5: 0.95 | B5: 13.62211 | C5: 11.367643 | D5: 10.340674 | E5: 9.5111541 | F5: 10.090403 | G5: 10.099364 | H5: 9.9426239 | I5: 10.404089 | J5: =(B5-H5)/B5 -> 0.27011134
A6: 1 | B6: 25.859523 | C6: 18.72995 | D6: 21.484183 | E6: 18.159122 | F6: 18.399833 | G6: 18.667329 | H6: 19.279514 | I6: 19.638414 | J6: =(B6-H6)/B6 -> 0.25445205
A7: 1.05 | B7: 37.465035 | C7: 32.872017 | D7: 34.615616 | E7: 31.398488 | F7: 36.554709 | G7: 36.297006 | H7: 30.045464 | I7: 33.783929 | J7: =(B7-H7)/B7 -> 0.19803988
A8: Grand Total | B8: 14.486801 | C8: 15.271471 | D8: 16.092096 | E8: 14.358382 | F8: 15.698857 | G8: 15.678649 | H8: 14.300119 | I8: 15.178974 | J8: =(B8-H8)/B8 -> 0.012886392
A34: V/C
B35: 0 | C35: 0.17 | D35: 0.33 | E35: 0.5 | F35: 0.67 | G35: 0.83 | H35: 1
A36: 0.5 | B36: 2.9974143 | C36: 2.8114831 | D36: 2.7034745 | E36: 2.5944321 | F36: 2.528139 | G36: 2.4660736 | H36: 2.4227644
A37: 0.67 | B37: 4.0959772 | C37: 3.5565853 | D37: 3.3446625 | E37: 3.1817646 | F37: 3.068922 | G37: 2.9944611 | H37: 2.9019804
A38: 0.95 | B38: 13.62211 | C38: 11.367643 | D38: 10.340674 | E38: 9.5111541 | F38: 10.090403 | G38: 10.099364 | H38: 9.9426239
A39: 1 | B39: 25.859523 | C39: 18.72995 | D39: 21.484183 | E39: 18.159122 | F39: 18.399833 | G39: 18.667329 | H39: 19.279514
A40: 1.05 | B40: 37.465035 | C40: 32.872017 | D40: 34.615616 | E40: 31.398488 | F40: 36.554709 | G40: 36.297006 | H40: 30.045464

Sheet STDI
A1: Average of INFORMED STD DEV | B1: Percent Informed
A2: Poisson arrival rate | B2: 0 | C2: 0.17 | D2: 0.33 | E2: 0.5 | F2: 0.67 | G2: 0.83 | H2: 1 | I2: Grand Total
A3: 0.5 | B3: 0 | C3: 0.76195316 | D3: 0.79476127 | E3: 0.79205068 | F3: 0.7962229 | G3: 0.79779937 | H3: 0.81202296 | I3: 0.67925862
A4: 0.67 | B4: 0 | C4: 1.2768834 | D4: 1.2954374 | E4: 1.3193917 | F4: 1.3556559 | G4: 1.3324287 | H4: 1.2805214 | I4: 1.1229026
A5: 0.95 | B5: 0 | C5: 5.9894983 | D5: 5.8717505 | E5: 5.784186 | F5: 6.1246503 | G5: 6.0131199 | H5: 5.9587468 | I5: 5.1059931
A6: 1 | B6: 0 | C6: 9.2299752 | D6: 11.433867 | E6: 9.803981 | F6: 9.790772 | G6: 9.939696 | H6: 10.2283 | I6: 8.6323702
A7: 1.05 | B7: 0 | C7: 16.859557 | D7: 17.058758 | E7: 16.473589 | F7: 18.55436 | G7: 19.135694 | H7: 16.292316 | I7: 14.910611
A8: Grand Total | B8: 0 | C8: 7.5554784 | D8: 8.1091969 | E8: 7.5763039 | F8: 8.1300069 | G8: 8.2783296 | H8: 7.6609612 | I8: 6.758611
A10: Average of INFORMED STD DEV | B10: Percent Informed
C11: 0.17 | D11: 0.33 | E11: 0.5 | F11: 0.67 | G11: 0.83 | H11: 1
B12: 0.5 | C12: 0.76195316 | D12: 0.79476127 | E12: 0.79205068 | F12: 0.7962229 | G12: 0.79779937 | H12: 0.81202296
B13: 0.67 | C13: 1.2768834 | D13: 1.2954374 | E13: 1.3193917 | F13: 1.3556559 | G13: 1.3324287 | H13: 1.2805214
B14: 0.95 | C14: 5.9894983 | D14: 5.8717505 | E14: 5.784186 | F14: 6.1246503 | G14: 6.0131199 | H14: 5.9587468
B15: 1 | C15: 9.2299752 | D15: 11.433867 | E15: 9.803981 | F15: 9.790772 | G15: 9.939696 | H15: 10.2283
B16: 1.05 | C16: 16.859557 | D16: 17.058758 | E16: 16.473589 | F16: 18.55436 | G16: 19.135694 | H16: 16.292316

Sheet STDU
A1: Average of UNINFORMED STD DEV | B1: Percent Informed
A2: Poisson arrival rate | B2: 0 | C2: 0.17 | D2: 0.33 | E2: 0.5 | F2: 0.67 | G2: 0.83 | H2: 1 | I2: Grand Total
A3: 0.5 | B3: 1.5032737 | C3: 1.3708949 | D3: 1.2417737 | E3: 1.1424538 | F3: 1.0904074 | G3: 1.0228906 | H3: 0 | I3: 1.0530992
A4: 0.67 | B4: 2.5418299 | C4: 2.0543665 | D4: 1.8294092 | E4: 1.6927731 | F4: 1.5907603 | G4: 1.4986835 | H4: 0 | I4: 1.6011175
A5: 0.95 | B5: 9.6311741 | C5: 6.9037168 | D5: 6.2564084 | E5: 5.951581 | F5: 6.2186868 | G5: 6.0176683 | H5: 0 | I5: 5.8541765
A6: 1 | B6: 14.067635 | C6: 10.203012 | D6: 11.739868 | E6: 9.8902466 | F6: 9.7986722 | G6: 9.9765723 | H6: 0 | I6: 9.3822865
A7: 1.05 | B7: 19.388437 | C7: 17.956759 | D7: 17.375467 | E7: 16.501579 | F7: 18.630155 | G7: 19.252014 | H7: 0 | I7: 15.586344
A8: Grand Total | B8: 10.285478 | C8: 8.4485894 | D8: 8.4967125 | E8: 7.7604544 | F8: 8.2596983 | G8: 8.3842396 | H8: 0 | I8: 7.3764531
A11: Average of UNINFORMED STD DEV | B11: Percent Informed
B12: 0 | C12: 0.17 | D12: 0.33 | E12: 0.5 | F12: 0.67 | G12: 0.83 | H12: 1 | I12: Grand Total
A13: 0.5 | B13: 1.5032737 | C13: 1.3708949 | D13: 1.2417737 | E13: 1.1424538 | F13: 1.0904074 | G13: 1.0228906 | H13: 0 | I13: 1.0530992
A14: 0.67 | B14: 2.5418299 | C14: 2.0543665 | D14: 1.8294092 | E14: 1.6927731 | F14: 1.5907603 | G14: 1.4986835 | H14: 0 | I14: 1.6011175
A15: 0.95 | B15: 9.6311741 | C15: 6.9037168 | D15: 6.2564084 | E15: 5.951581 | F15: 6.2186868 | G15: 6.0176683 | H15: 0 | I15: 5.8541765
A16: 1 | B16: 14.067635 | C16: 10.203012 | D16: 11.739868 | E16: 9.8902466 | F16: 9.7986722 | G16: 9.9765723 | H16: 0 | I16: 9.3822865
A17: 1.05 | B17: 19.388437 | C17: 17.956759 | D17: 17.375467 | E17: 16.501579 | F17: 18.630155 | G17: 19.252014 | H17: 0 | I17: 15.586344
A18: Grand Total | B18: 10.285478 | C18: 8.4485894 | D18: 8.4967125 | E18: 7.7604544 | F18: 8.2596983 | G18: 8.3842396 | H18: 0 | I18: 7.3764531

Sheet DELTASTD
B1: =STDI!B1 -> Percent Informed | K1: Average Time Overall
C2: 0.17 | D2: 0.33 | E2: 0.5 | F2: 0.67 | G2: 0.83 | I2: =STDI!I2 -> Grand Total | K2: Grand Total
B3: 0.5 | C3: -0.60894172 | D3: -0.44701242 | E3: -0.35040312 | F3: -0.2941845 | G3: -0.22509127 | I3: =STDI!I3-STDU!I3 -> -0.37384054 | K3: 2.6462544
B4: 0.67 | C4: -0.77748313 | D4: -0.53397175 | E4: -0.37338141 | F4: -0.23510439 | G4: -0.16625479 | I4: =STDI!I4-STDU!I4 -> -0.47821486 | K4: 3.223216
B5: 0.95 | C5: -0.91421844 | D5: -0.38465794 | E5: -0.16739494 | F5: -0.094036515 | G5: -0.004548364 | I5: =STDI!I5-STDU!I5 -> -0.74818336 | K5: 10.404089
B6: 1 | C6: -0.97303678 | D6: -0.3060007 | E6: -0.08626562 | F6: -0.0079001983 | G6: -0.036876253 | I6: =STDI!I6-STDU!I6 -> -0.74991628 | K6: 19.638414
B7: 1.05 | C7: -1.0972025 | D7: -0.31670903 | E7: -0.027989374 | F7: -0.07579447 | G7: -0.11632031 | I7: =STDI!I7-STDU!I7 -> -0.67573378 | K7: 33.783929
I8: =STDI!I8-STDU!I8 -> -0.61784215 | K8: 15.178974
B12: Standard Deviation Informed - Uninformed (all else equal)

Sheet TSI
A1: Average of Informed %Savings | B1: Percent Informed
A2: Poisson arrival rate | B2: 0 | C2: 0.17 | D2: 0.33 | E2: 0.5 | F2: 0.67 | G2: 0.83 | H2: 1 | I2: Grand Total
A3: 0.5 | B3: =#REF! -> #DIV/0! | C3: 0.21135813 | D3: 0.20366357 | E3: 0.20173583 | F3: 0.19633418 | G3: 0.19593055 | H3: 0.19171409 | I3: 0.20012272
A4: 0.67 | B4: =#REF! -> #DIV/0! | C4: 0.29340716 | D4: 0.28194772 | E4: 0.27626925 | F4: 0.27122561 | G4: 0.26788754 | H4: 0.27450992 | I4: 0.2775412
A5: 0.95 | B5: =#REF! -> #DIV/0! | C5: 0.3589287 | D5: 0.36356478 | E5: 0.39127072 | F5: 0.33717389 | G5: 0.32418628 | H5: 0.32929443 | I5: 0.35073647
A6: 1 | B6: =#REF! -> #DIV/0! | C6: 0.3676765 | D6: 0.22035633 | E6: 0.32556053 | F6: 0.31090768 | G6: 0.29339264 | H6: 0.26194436 | I6: 0.29663967
A7: 1.05 | B7: =#REF! -> #DIV/0! | C7: 0.21685763 | D7: 0.13482903 | E7: 0.20606352 | F7: 0.067490939 | G7: 0.068789235 | H7: 0.22649028 | I7: 0.15342011
A8: Grand Total | B8: =#REF! -> #DIV/0! | C8: 0.28995403 | D8: 0.23342763 | E8: 0.27848962 | F8: 0.2310468 | G8: 0.22427886 | H8: 0.25531141 | I8: 0.25208472
C9: 0.17 | D9: 0.33 | E9: 0.5 | F9: 0.67 | G9: 0.83 | H9: 1
B10: 0.5 | C10: 0.21135813 | D10: 0.20366357 | E10: 0.20173583 | F10: 0.19633418 | G10: 0.19593055 | H10: 0.19171409 | I10: 0.20012272
B11: 0.67 | C11: 0.29340716 | D11: 0.28194772 | E11: 0.27626925 | F11: 0.27122561 | G11: 0.26788754 | H11: 0.27450992 | I11: 0.2775412
B12: 0.95 | C12: 0.3589287 | D12: 0.36356478 | E12: 0.39127072 | F12: 0.33717389 | G12: 0.32418628 | H12: 0.32929443 | I12: 0.35073647
B13: 1 | C13: 0.3676765 | D13: 0.22035633 | E13: 0.32556053 | F13: 0.31090768 | G13: 0.29339264 | H13: 0.26194436 | I13: 0.29663967
B14: 1.05 | C14: 0.21685763 | D14: 0.13482903 | E14: 0.20606352 | F14: 0.067490939 | G14: 0.068789235 | H14: 0.22649028 | I14: 0.15342011

Sheet TSU
A1: Average of Uninformed %Savings | B1: Percent Informed
A2: Poisson arrival rate | B2: 0 | C2: 0.17 | D2: 0.33 | E2: 0.5 | F2: 0.67 | G2: 0.83 | H2: 1 | I2: Grand Total
A3: 0.5 | C3: 0.031222477 | D3: 0.046229305 | E3: 0.066317753 | F3: 0.075668526 | G3: 0.086774175 | H3: =#REF! -> #DIV/0! | I3: 0.061242447
A4: 0.67 | B4: =#REF! -> #DIV/0! | C4: 0.073384988 | D4: 0.10578911 | E4: 0.13274572 | F4: 0.15641219 | G4: 0.17074137 | H4: =#REF! -> #DIV/0! | I4: 0.12781468
A5: 0.95 | C5: 0.20935293 | D5: 0.27698294 | E5: 0.3303173 | F5: 0.28917738 | G5: 0.27879912 | H5: =#REF! -> #DIV/0! | I5: 0.27692593
A6: 1 | B6: =#REF! -> #DIV/0! | C6: 0.26785016 | D6: 0.16128504 | E6: 0.29029138 | F6: 0.28285653 | G6: 0.26973948 | H6: =#REF! -> #DIV/0! | I6: 0.25440452
A7: 1.05 | B7: =#REF! -> #DIV/0! | C7: 0.13991461 | D7: 0.095004678 | E7: 0.17737081 | F7: 0.048401961 | G7: 0.053739907 | H7: =#REF! -> #DIV/0! | I7: 0.10288639
A8: Grand Total | B8: =#REF! -> #DIV/0! | C8: 0.15134943 | D8: 0.13600958 | E8: 0.2034583 | F8: 0.1699299 | G8: 0.17075656 | H8: =#REF! -> #DIV/0! | I8: 0.16630075
A11: Poisson arrival rate | C11: 0.17 | D11: 0.33 | E11: 0.5 | F11: 0.67 | G11: 0.83
B12: 0.5 | C12: 0.031222477 | D12: 0.046229305 | E12: 0.066317753 | F12: 0.075668526 | G12: 0.086774175
B13: 0.67 | C13: 0.073384988 | D13: 0.10578911 | E13: 0.13274572 | F13: 0.15641219 | G13: 0.17074137
B14: 0.95 | C14: 0.20935293 | D14: 0.27698294 | E14: 0.3303173 | F14: 0.28917738 | G14: 0.27879912
B15: 1 | C15: 0.26785016 | D15: 0.16128504 | E15: 0.29029138 | F15: 0.28285653 | G15: 0.26973948
B16: 1.05 | C16: 0.13991461 | D16: 0.095004678 | E16: 0.17737081 | F16: 0.048401961 | G16: 0.053739907

Sheet Summary
A2: Poisson arrival rate | B2: Percent Informed | C2: Time Informed | D2: Time Uninformed | E2: Time Overall | F2: Informed %Savings | G2: Uninformed %Savings | H2: INFORMED STD DEV | I2: UNINFORMED STD DEV
A3: 1.05 | B3: 1 | C3: 31.682477 | E3: 31.682477 | F3: 0.24489711 | H3: 16.587082 | I3: 0
A4: 1.05 | B4: 0.83 | C4: 39.185828 | D4: 40.074984 | E4: 39.336095 | F4: 0.066066342 | G4: 0.044874692 | H4: 21.366129 | I4: 21.231431
A5: 1.05 | B5: 0.67 | C5: 40.712978 | D5: 41.832497 | E5: 41.080293 | F5: 0.029669075 | G5: 0.0029870724 | H5: 20.971842 | I5: 20.756245
A6: 1.05 | B6: 0.5 | C6: 32.070954 | D6: 33.072158 | E6: 32.567985 | F6: 0.23563838 | G6: 0.21177623 | H6: 17.302079 | I6: 16.917287
A7: 1.05 | B7: 0.33 | C7: 33.972686 | D7: 35.570586 | E7: 35.045623 | F7: 0.19031352 | G7: 0.15223004 | H7: 18.095706 | I7: 18.227142
A8: 1.05 | B8: 0.17 | C8: 30.294412 | D8: 33.81784 | E8: 33.20817 | F8: 0.2779795 | G8: 0.19400404 | H8: 16.389283 | I8: 17.575058
A9: 1.05 | B9: 0 | D9: 41.957828 | H9: 0 | I9: 19.978538
A10: 1 | B10: 1 | C10: 17.735895 | E10: 17.735895 | F10: 0.40053036 | H10: 9.7195623 | I10: 0
A11: 1 | B11: 0.83 | C11: 18.370991 | D11: 18.636773 | E11: 18.41582 | F11: 0.37906423 | G11: 0.37008086 | H11: 10.446204 | I11: 10.204545
A12: 1 | B12: 0.67 | C12: 18.760715 | D12: 19.507912 | E12: 19.012047 | F12: 0.36589164 | G12: 0.34063653 | H12: 10.000721 | I12: 9.9682496
A13: 1 | B13: 0.5 | C13: 18.348034 | D13: 19.372805 | E13: 18.864587 | F13: 0.37984018 | G13: 0.34520312 | H13: 10.000025 | I13: 9.9191119
A14: 1 | B14: 0.33 | C14: 19.279058 | D14: 20.646117 | E14: 20.193028 | F14: 0.34837174 | G14: 0.30216543 | H14: 10.767779 | I14: 11.13475
A15: 1 | B15: 0.17 | C15: 15.236069 | D15: 17.976165 | E15: 17.506421 | F15: 0.48502398 | G15: 0.39240929 | H15: 8.6072455 | I15: 9.6654922
A16: 1 | B16: 0 | D16: 29.585977 | H16: 0 | I16: 16.139099
A17: 0.95 | B17: 1 | C17: 9.8934549 | E17: 9.8934549 | F17: 0.34690223 | H17: 5.5278838 | I17: 0
A18: 0.95 | B18: 0.83 | C18: 9.2986062 | D18: 9.8788433 | E18: 9.3999543 | F18: 0.38617004 | G18: 0.34786679 | H18: 5.8449556 | I18: 5.7705817
A19: 0.95 | B19: 0.67 | C19: 9.8927857 | D19: 10.557592 | E19: 10.117158 | F19: 0.3469464 | G19: 0.30306047 | H19: 6.0444989 | I19: 6.0468241
A20: 0.95 | B20: 0.5 | C20: 9.1441328 | D20: 10.035877 | E20: 9.5893508 | F20: 0.39636731 | G20: 0.33750051 | H20: 5.5871675 | I20: 5.6935427
A21: 0.95 | B21: 0.33 | C21: 9.522044 | D21: 10.818889 | E21: 10.394907 | F21: 0.37142021 | G21: 0.28581146 | H21: 5.8266719 | I21: 6.0362923
A22: 0.95 | B22: 0.17 | C22: 10.114132 | D22: 12.489111 | E22: 12.080298 | F22: 0.33233464 | G22: 0.17555491 | H22: 6.313128 | I22: 7.0116455
A23: 0.95 | B23: 0 | D23: 15.148505 | H23: 0 | I23: 9.8046489
A24: 0.67 | B24: 1 | C24: 2.9115742 | E24: 2.9115742 | F24: 0.25968868 | H24: 1.2746611 | I24: 0
A25: 0.67 | B25: 0.83 | C25: 2.9093896 | D25: 3.3023762 | E25: 2.9762104 | F25: 0.26024413 | G25: 0.16032143 | H25: 1.2971508 | I25: 1.4793351
A26: 0.67 | B26: 0.67 | C26: 2.8909978 | D26: 3.3560293 | E26: 3.0483645 | F26: 0.26492052 | G26: 0.14667931 | H26: 1.3214767 | I26: 1.5865201
A27: 0.67 | B27: 0.5 | C27: 2.865306 | D27: 3.4478998 | E27: 3.1538841 | F27: 0.27145305 | G27: 0.12331987 | H27: 1.2682469 | I27: 1.6676544
A28: 0.67 | B28: 0.33 | C28: 2.8969059 | D28: 3.5920887 | E28: 3.3618673 | F28: 0.26341832 | G28: 0.086657684 | H28: 1.3260655 | I28: 1.8473322
A29: 0.67 | B29: 0.17 | C29: 2.8097927 | D29: 3.6473139 | E29: 3.5045444 | F29: 0.28556815 | G29: 0.072615845 | H29: 1.2431327 | I29: 1.9695739
A30: 0.67 | B30: 0 | D30: 3.9329051 | H30: 0 | I30: 2.5592495
A31: 0.5 | B31: 1 | C31: 2.4245431 | E31: 2.4245431 | F31: 0.19070977 | H31: 0.82390855 | I31: 0
A32: 0.5 | B32: 0.83 | C32: 2.4161376 | D32: 2.7562563 | E32: 2.4732436 | F32: 0.19351543 | G32: 0.07998693 | H32: 0.81575665 | I32: 1.0740898
A33: 0.5 | B33: 0.67 | C33: 2.4080467 | D33: 2.7687624 | E33: 2.527107 | F33: 0.1962161 | G33: 0.075812504 | H33: 0.79879004 | I33: 1.0652833
A34: 0.5 | B34: 0.5 | C34: 2.3908972 | D34: 2.798256 | E34: 2.5920102 | F34: 0.20194047 | G34: 0.065967824 | H34: 0.78655358 | I34: 1.1169052
A35: 0.5 | B35: 0.33 | C35: 2.3821458 | D35: 2.8650651 | E35: 2.7061042 | F35: 0.20486158 | G35: 0.043667552 | H35: 0.8067439 | I35: 1.2310727
A36: 0.5 | B36: 0.17 | C36: 2.371512 | D36: 2.8755035 | E36: 2.7894721 | F36: 0.20841104 | G36: 0.040183328 | H36: 0.75412705 | I36: 1.369245
A37: 0.5 | B37: 0 | D37: 2.9958882 | E37: 2.9958882 | H37: 0 | I37: 1.5298791
A38: 1.05 | B38: 1 | C38: 31.63931 | E38: 31.63931 | F38: 0.15549766 | H38: 16.62119 | I38: 0
A39: 1.05 | B39: 0.83 | C39: 37.527361 | D39: 38.037644 | E39: 37.613837 | F39: -0.001663568 | G39: -0.015283835 | H39: 19.129896 | I39: 19.780879
A40: 1.05 | B40: 0.67 | C40: 30.561006 | D40: 31.416122 | E40: 30.840002 | F40: 0.18427926 | G40: 0.16145489 | H40: 16.278391 | I40: 16.442894
A41: 1.05 | B41: 0.5 | C41: 29.05247 | D41: 30.600582 | E41: 29.83246 | F41: 0.22454443 | G41: 0.18322293 | H41: 16.877793 | I41: 16.968398
...

Sheet RESULTS
A1: Poisson | B1: Freeway | C1: Arterial | D1: Freeway | E1: Demand | F1: Alternate | G1: Percent | H1: MEAN | L1: STD.DEV | P1: N
A2: arrival rate | B2: Service time mean | D2: range | E2: Coefficient | F2: Time | G2: Informed | H2: FREEWAY | I2: FREEWAY | J2: ARTERIAL | K2: ARTERIAL | L2: FREEWAY | M2: FREEWAY | N2: ARTERIAL | O2: ARTERIAL | P2: FREEWAY | Q2: FREEWAY | R2: ARTERIAL | S2: ARTERIAL | T2: Time | W2: Informed | X2: Uninformed
A3: (cust/sec) | B3: (sec) | F3: (sec) | H3: INFORMED | I3: UNINFORMED | J3: INFORMED | K3: UNINFORMED | L3: INFORMED | M3: UNINFORMED | N3: INFORMED | O3: UNINFORMED | P3: INFORMED | Q3: UNINFORMED | R3: INFORMED | S3: UNINFORMED | T3: Informed | U3: Uninformed | V3: Overall | W3: %Savings | X3: %Savings
A5: 1.05 | B5: 2 | C5: 2 | D5: 0.5 | E5: -0.15 | F5: 0 | G5: 1 | H5: 31.684411 | I5: 0 | J5: 31.680541 | K5: 0 | L5: 16.587082 | M5: 0 | N5: 16.527711 | O5: 0 | P5: 15009 | Q5: 0 | R5: 14991 | S5: 0 | T5: =(H5*P5+J5*R5)/(P5+R5) -> 31.682477 | V5: =(H5*P5+I5*Q5+J5*R5+K5*S5)/(P5+Q5+R5+S5) -> 31.682477 | W5: =($U$11-T5)/($U$11) -> 0.24489711
A6: 1.05 | B6: 2 | C6: 2 | D6: 0.5 | E6: -0.15 | F6: 0 | G6: 0.83 | H6: 39.107579 | I6: 40.002543 | J6: 39.264746 | K6: 40.146178 | L6: 21.366129 | M6: 21.231431 | N6: 21.342568 | O6: 21.0378 | P6: 12518 | Q6: 2513 | R6: 12412 | S6: 2557 | T6: =(H6*P6+J6*R6)/(P6+R6) -> 39.185828 | U6: =(I6*Q6+K6*S6)/(Q6+S6) -> 40.074984 | V6: =(H6*P6+I6*Q6+J6*R6+K6*S6)/(P6+Q6+R6+S6) -> 39.336095 | W6: =($U$11-T6)/($U$11) -> 0.066066342 | X6: =($U$11-U6)/($U$11) -> 0.044874692
A7: 1.05 | B7: 2 | C7: 2 | D7: 0.5 | E7: -0.15 | F7: 0 | G7: 0.67 | H7: 40.702355 | I7: 41.914419 | J7: 40.723402 | K7: 41.747333 | L7: 20.971842 | M7: 20.756245 | N7: 20.86166 | O7: 20.606101 | P7: 9983 | Q7: 5017 | R7: 10174 | S7: 4826 | T7: =(H7*P7+J7*R7)/(P7+R7) -> 40.712978 | U7: =(I7*Q7+K7*S7)/(Q7+S7) -> 41.832497 | V7: =(H7*P7+I7*Q7+J7*R7+K7*S7)/(P7+Q7+R7+S7) -> 41.080293 | W7: =($U$11-T7)/($U$11) -> 0.029669075 | X7: =($U$11-U7)/($U$11) -> 0.0029870724
A8: 1.05 | B8: 2 | C8: 2 | D8: 0.5 | E8: -0.15 | F8: 0 | G8: 0.5 | H8: 31.992867 | I8: 33.184712 | J8: 32.148412 | K8: 32.958219 | L8: 17.302079 | M8: 16.917287 | N8: 17.002178 | O8: 17.086225 | P8: 7523 | Q8: 7492 | R8: 7584 | S8: 7401 | T8: =(H8*P8+J8*R8)/(P8+R8) -> 32.070954 | U8: =(I8*Q8+K8*S8)/(Q8+S8) -> 33.072158 | V8: =(H8*P8+I8*Q8+J8*R8+K8*S8)/(P8+Q8+R8+S8) -> 32.567985 | W8: =($U$11-T8)/($U$11) -> 0.23563838 | X8: =($U$11-U8)/($U$11) -> 0.21177623
A9: 1.05 | B9: 2 | C9: 2 | D9: 0.5 | E9: -0.15 | F9: 0 | G9: 0.33 | H9: 34.206931 | I9: 35.443044 | J9: 33.74454 | K9: 35.70012 | L9: 18.095706 | M9: 18.227142 | N9: 17.771676 | O9: 18.375616 | P9: 4863 | Q9: 10150 | R9: 4993 | S9: 9994 | T9: =(H9*P9+J9*R9)/(P9+R9) -> 33.972686 | U9: =(I9*Q9+K9*S9)/(Q9+S9) -> 35.570586 | V9: =(H9*P9+I9*Q9+J9*R9+K9*S9)/(P9+Q9+R9+S9) -> 35.045623 | W9: =($U$11-T9)/($U$11) -> 0.19031352 | X9: =($U$11-U9)/($U$11) -> 0.15223004
A10: 1.05 | B10: 2 | C10: 2 | D10: 0.5 | E10: -0.15 | F10: 0 | G10: 0.17 | H10: 29.818724 | I10: 33.872879 | J10: 30.771753 | K10: 33.762699 | L10: 16.389283 | M10: 17.575058 | N10: 16.780524 | O10: 17.376178 | P10: 2600 | Q10: 12416 | R10: 2591 | S10: 12393 | T10: =(H10*P10+J10*R10)/(P10+R10) -> 30.294412 | U10: =(I10*Q10+K10*S10)/(Q10+S10) -> 33.81784 | V10: =(H10*P10+I10*Q10+J10*R10+K10*S10)/(P10+Q10+R10+S10) -> 33.20817 | W10: =($U$11-T10)/($U$11) -> 0.2779795 | X10: =($U$11-U10)/($U$11) -> 0.19400404
A11: 1.05 | B11: 2 | C11: 2 | D11: 0.5 | E11: -0.15 | F11: 0 | G11: 0 | H11: 0 | I11: 37.427514 | J11: 0 | K11: 46.412073 | L11: 0 | M11: 19.978538 | N11: 0 | O11: 25.656406 | P11: 0 | Q11: 14873 | R11: 0 | S11: 15127 | U11: =(I11*Q11+K11*S11)/(Q11+S11) -> 41.957828
A12: 1 | B12: 2 | C12: 2 | D12: 0.5 | E12: -0.15 | F12: 0 | G12: 1 | H12: 17.750001 | I12: 0 | J12: 17.72179 | K12: 0 | L12: 9.7195623 | M12: 0 | N12: 9.7141449 | O12: 0 | P12: 14999 | Q12: 0 | R12: 15001 | S12: 0 | T12: =(H12*P12+J12*R12)/(P12+R12) -> 17.735895 | V12: =(H12*P12+I12*Q12+J12*R12+K12*S12)/(P12+Q12+R12+S12) -> 17.735895 | W12: =($U$18-T12)/($U$18) -> 0.40053036
A13: 1 | B13: 2 | C13: 2 | D13: 0.5 | E13: -0.15 | F13: 0 | G13: 0.83 | H13: 18.383866 | I13: 18.455802 | J13: 18.358069 | K13: 18.815893 | L13: 10.446204 | M13: 10.204545 | N13: 10.435674 | O13: 10.226003 | P13: 12493 | Q13: 2517 | R13: 12447 | S13: 2543 | T13: =(H13*P13+J13*R13)/(P13+R13) -> 18.370991 | U13: =(I13*Q13+K13*S13)/(Q13+S13) -> 18.636773 | V13: =(H13*P13+I13*Q13+J13*R13+K13*S13)/(P13+Q13+R13+S13) -> 18.41582 | W13: =($U$18-T13)/($U$18) -> 0.37906423 | X13: =($U$18-U13)/($U$18) -> 0.37008086
A14: 1 | B14: 2 | C14: 2 | D14: 0.5 | E14: -0.15 | F14: 0 | G14: 0.67 | H14: 18.726792 | I14: 19.541233 | J14: 18.794786 | K14: 19.474757 | L14: 10.000721 | M14: 9.9682496 | N14: 9.9517624 | O14: 9.9913236 | P14: 9976 | Q14: 5033 | R14: 9933 | S14: 5058 | T14: =(H14*P14+J14*R14)/(P14+R14) -> 18.760715 | U14: =(I14*Q14+K14*S14)/(Q14+S14) -> 19.507912 | V14: =(H14*P14+I14*Q14+J14*R14+K14*S14)/(P14+Q14+R14+S14) -> 19.012047 | W14: =($U$18-T14)/($U$18) -> 0.36589164 | X14: =($U$18-U14)/($U$18) -> 0.34063653
A15: 1 | B15: 2 | C15: 2 | D15: 0.5 | E15: -0.15 | F15: 0 | G15: 0.5 | H15: 18.452062 | I15: 19.186196 | J15: 18.243641 | K15: 19.55981 | L15: 10.000025 | M15: 9.9191119 | N15: 9.7387426 | O15: 10.140356 | P15: 7452 | Q15: 7569 | R15: 7426 | S15: 7553 | T15: =(H15*P15+J15*R15)/(P15+R15) -> 18.348034 | U15: =(I15*Q15+K15*S15)/(Q15+S15) -> 19.372805 | V15: =(H15*P15+I15*Q15+J15*R15+K15*S15)/(P15+Q15+R15+S15) -> 18.864587 | W15: =($U$18-T15)/($U$18) -> 0.37984018 | X15: =($U$18-U15)/($U$18) -> 0.34520312
A16: 1 | B16: 2 | C16: 2 | D16: 0.5 | E16: -0.15 | F16: 0 | G16: 0.33 | H16: 18.842882 | I16: 20.777686 | J16: 19.722043 | K16: 20.515086 | L16: 10.767779 | M16: 11.13475 | N16: 10.846564 | O16: 10.923968 | P16: 5010 | Q16: 10008 | R16: 4933 | S16: 10049 | T16: =(H16*P16+J16*R16)/(P16+R16) -> 19.279058 | U16: =(I16*Q16+K16*S16)/(Q16+S16) -> 20.646117 | V16: =(H16*P16+I16*Q16+J16*R16+K16*S16)/(P16+Q16+R16+S16) -> 20.193028 | W16: =($U$18-T16)/($U$18) -> 0.34837174 | X16: =($U$18-U16)/($U$18) -> 0.30216543
A17: 1 | B17: 2 | C17: 2 | D17: 0.5 | E17: -0.15 | F17: 0 | G17: 0.17 | H17: 14.985878 | I17: 17.709691 | J17: 15.494869 | K17: 18.242531 | L17: 8.6072455 | M17: 9.6654922 | N17: 8.946753 | O17: 9.684633 | P17: 2615 | Q17: 12426 | R17: 2528 | S17: 12431 | T17: =(H17*P17+J17*R17)/(P17+R17) -> 15.236069 | U17: =(I17*Q17+K17*S17)/(Q17+S17) -> 17.976165 | V17: =(H17*P17+I17*Q17+J17*R17+K17*S17)/(P17+Q17+R17+S17) -> 17.506421 | W17: =($U$18-T17)/($U$18) -> 0.48502398 | X17: =($U$18-U17)/($U$18) -> 0.39240929
A18: 1 | B18: 2 | C18: 2 | D18: 0.5 | E18: -0.15 | F18: 0 | G18: 0 | H18: 0 | I18: 28.660292 | J18: 0 | K18: 30.512526 | L18: 0 | M18: 16.139099 | N18: 0 | O18: 15.732407 | P18: 0 | Q18: 15007 | R18: 0 | S18: 14993 | U18: =(I18*Q18+K18*S18)/(Q18+S18) -> 29.585977
A19: 0.95 | B19: 2 | C19: 2 | D19: 0.5 | E19: -0.15 | F19: 0 | G19: 1 | H19: 9.8877474 | I19: 0 | J19: 9.8991807 | K19: 0 | L19: 5.5278838 | M19: 0 | N19: 5.5340246 | O19: 0 | P19: 15024 | Q19: 0 | R19: 14976 | S19: 0 | T19: =(H19*P19+J19*R19)/(P19+R19) -> 9.8934549 | V19: =(H19*P19+I19*Q19+J19*R19+K19*S19)/(P19+Q19+R19+S19) -> 9.8934549 | W19: =($U$25-T19)/($U$25) -> 0.34690223
A20: 0.95 | B20: 2 | C20: 2 | D20: 0.5 | E20: -0.15 | F20: 0 | G20: 0.83 | H20: 9.2823553 | I20: 9.9153879 | J20: 9.314894 | K20: 9.8419905 | L20: 5.8449556 | M20: 5.7705817 | N20: 5.794794 | O20: 5.937384 | P20: 12394 | Q20: 2631 | R20: 12366 | S20: 2609 | T20: =(H20*P20+J20*R20)/(P20+R20) -> 9.2986062 | U20: =(I20*Q20+K20*S20)/(Q20+S20) -> 9.8788433 | V20: =(H20*P20+I20*Q20+J20*R20+K20*S20)/(P20+Q20+R20+S20) -> 9.3999543 | W20: =($U$25-T20)/($U$25) -> 0.38617004 | X20: =($U$25-U20)/($U$25) -> 0.34786679
A21: 0.95 | B21: 2 | C21: 2 | D21: 0.5 | E21: -0.15 | F21: 0 | G21: 0.67 | H21: 9.9989551 | I21: 10.329489 | J21: 9.7873721 | K21: 10.792695 | L21: 6.0444989 | M21: 6.0468241 | N21: 5.9907312 | O21: 6.2987561 | P21: 9902 | Q21: 5139 | R21: 9973 | S21: 4986 | T21: =(H21*P21+J21*R21)/(P21+R21) -> 9.8927857 | U21: =(I21*Q21+K21*S21)/(Q21+S21) -> 10.557592 | V21: =(H21*P21+I21*Q21+J21*R21+K21*S21)/(P21+Q21+R21+S21) -> 10.117158 | W21: =($U$25-T21)/($U$25) -> 0.3469464 | X21: =($U$25-U21)/($U$25) -> 0.30306047
A22: 0.95 | B22: 2 | C22: 2 | D22: 0.5 | E22: -0.15 | F22: 0 | G22: 0.5 | H22: 9.2022432 | I22: 10.000419 | J22: 9.0875645 | K22: 10.07249 | L22: 5.5871675 | M22: 5.6935427 | N22: 5.5302215 | O22: 5.7838841 | P22: 7410 | Q22: 7609 | R22: 7612 | S22: 7369 | T22: =(H22*P22+J22*R22)/(P22+R22) -> 9.1441328 | U22: =(I22*Q22+K22*S22)/(Q22+S22) -> 10.035877 | V22: =(H22*P22+I22*Q22+J22*R22+K22*S22)/(P22+Q22+R22+S22) -> 9.5893508 | W22: =($U$25-T22)/($U$25) -> 0.39636731 | X22: =($U$25-U22)/($U$25) -> 0.33750051
A23: 0.95 | B23: 2 | C23: 2 | D23: 0.5 | E23: -0.15 | F23: 0 | G23: 0.33 | H23: 9.4747697 | I23: 10.678574 | J23: 9.5705686 | K23: 10.957656 | L23: 5.8266719 | M23: 6.0362923 | N23: 5.8921933 | O23: 6.3151683 | P23: 4968 | Q23: 10040 | R23: 4840 | S23: 10152 | T23: =(H23*P23+J23*R23)/(P23+R23) -> 9.522044 | U23: =(I23*Q23+K23*S23)/(Q23+S23) -> 10.818889 | V23: =(H23*P23+I23*Q23+J23*R23+K23*S23)/(P23+Q23+R23+S23) -> 10.394907 | W23: =($U$25-T23)/($U$25) -> 0.37142021 | X23: =($U$25-U23)/($U$25) -> 0.28581146
A24: 0.95 | B24: 2 | C24: 2 | D24: 0.5 | E24: -0.15 | F24: 0 | G24: 0.17 | H24: 10.296591 | I24: 12.180518 | J24: 9.9189482 | K24: 12.79165 | L24: 6.313128 | M24: 7.0116455 | N24: 6.2041245 | O24: 7.5345641 | P24: 2669 | Q24: 12295 | R24: 2495 | S24: 12541 | T24: =(H24*P24+J24*R24)/(P24+R24) -> 10.114132 | U24: =(I24*Q24+K24*S24)/(Q24+S24) -> 12.489111 | V24: =(H24*P24+I24*Q24+J24*R24+K24*S24)/(P24+Q24+R24+S24) -> 12.080298 | W24: =($U$25-T24)/($U$25) -> 0.33233464 | X24: =($U$25-U24)/($U$25) -> 0.17555491
A25: 0.95 | B25: 2 | C25: 2 | D25: 0.5 | E25: -0.15 | F25: 0 | G25: 0 | H25: 0 | I25: 15.727406 | J25: 0 | K25: 14.557988 | L25: 0 | M25: 9.8046489 | N25: 0 | O25: 8.9587801 | P25: 0 | Q25: 15149 | R25: 0 | S25: 14851 | U25: =(I25*Q25+K25*S25)/(Q25+S25) -> 15.148505
A26: 0.67 | B26: 2 | C26: 2 | D26: 0.5 | E26: -0.15 | F26: 0 | G26: 1 | H26: 2.9083785 | I26: 0 | J26: 2.914786 | K26: 0 | L26: 1.2746611 | M26: 0 | N26: 1.2729531 | O26: 0 | P26: 15038 | Q26: 0 | R26: 14962 | S26: 0 | T26: =(H26*P26+J26*R26)/(P26+R26) -> 2.9115742 | V26: =(H26*P26+I26*Q26+J26*R26+K26*S26)/(P26+Q26+R26+S26) -> 2.9115742 | W26: =($U$32-T26)/($U$32) -> 0.25968868
A27: 0.67 | B27: 2 | C27: 2 | D27: 0.5 | E27: -0.15 | F27: 0 | G27: 0.83 | H27: 2.9071379 | I27: 3.3236805 | J27: 2.9116492 | K27: 3.2812796 | L27: 1.2971508 | M27: 1.4793351 | N27: 1.2951717 | O27: 1.4278526 | P27: 12471 | Q27: 2538 | R27: 12428 | S27: 2563 | T27: =(H27*P27+J27*R27)/(P27+R27) -> 2.9093896 | U27: =(I27*Q27+K27*S27)/(Q27+S27) -> 3.3023762 | V27: =(H27*P27+I27*Q27+J27*R27+K27*S27)/(P27+Q27+R27+S27) -> 2.9762104 | W27: =($U$32-T27)/($U$32) -> 0.26024413 | X27: =($U$32-U27)/($U$32) -> 0.16032143
A28: 0.67 | B28: 2 | C28: 2 | D28: 0.5 | E28: -0.15 | F28: 0 | G28: 0.67 | H28: 2.8941684 | I28: 3.3574515 | J28: 2.8877764 | K28: 3.3545987 | L28: 1.3214767 | M28: 1.5865201 | N28: 1.3046132 | O28: 1.5508135 | P28: 10003 | Q28: 5091 | R28: 9845 | S28: 5061 | T28: =(H28*P28+J28*R28)/(P28+R28) -> 2.8909978 | U28: =(I28*Q28+K28*S28)/(Q28+S28) -> 3.3560293 | V28: =(H28*P28+I28*Q28+J28*R28+K28*S28)/(P28+Q28+R28+S28) -> 3.0483645 | W28: =($U$32-T28)/($U$32) -> 0.26492052 | X28: =($U$32-U28)/($U$32) -> 0.14667931
A29: 0.67 | B29: 2 | C29: 2 | D29: 0.5 | E29: -0.15 | F29: 0 | G29: 0.5 | H29: 2.8562731 | I29: 3.4352242 | J29: 2.8744229 | K29: 3.4603823 | L29: 1.2682469 | M29: 1.6676544 | N29: 1.2691449 | O29: 1.6535623 | P29: 7605 | Q29: 7373 | R29: 7535 | S29: 7487 | T29: =(H29*P29+J29*R29)/(P29+R29) -> 2.865306 | U29: =(I29*Q29+K29*S29)/(Q29+S29) -> 3.4478998 | V29: =(H29*P29+I29*Q29+J29*R29+K29*S29)/(P29+Q29+R29+S29) -> 3.1538841 | W29: =($U$32-T29)/($U$32) -> 0.27145305 | X29: =($U$32-U29)/($U$32) -> 0.12331987
A30: 0.67 | B30: 2 | C30: 2 | D30: 0.5 | E30: -0.15 | F30: 0 | G30: 0.33 | H30: 2.8819216 | I30: 3.5880102 | J30: 2.9121364 | K30: 3.5961166 | L30: 1.3260655 | M30: 1.8473322 | N30: 1.3458218 | O30: 1.8640083 | P30: 5008 | Q30: 9970 | R30: 4927 | S30: 10095 | T30: =(H30*P30+J30*R30)/(P30+R30) -> 2.8969059 | U30: =(I30*Q30+K30*S30)/(Q30+S30) -> 3.5920887 | V30: =(H30*P30+I30*Q30+J30*R30+K30*S30)/(P30+Q30+R30+S30) -> 3.3618673 | W30: =($U$32-T30)/($U$32) -> 0.26341832 | X30: =($U$32-U30)/($U$32) -> 0.086657684
A31: 0.67 | B31: 2 | C31: 2 | D31: 0.5 | E31: -0.15 | F31: 0 | G31: 0.17 | H31: 2.8194536 | I31: 3.6393945 | J31: 2.799715 | K31: 3.655102 | L31: 1.2431327 | M31: 1.9695739 | N31: 1.2111497 | O31: 1.9715289 | P31: 2611 | Q31: 12339 | R31: 2503 | S31: 12547 | T31: =(H31*P31+J31*R31)/(P31+R31) -> 2.8097927 | U31: =(I31*Q31+K31*S31)/(Q31+S31) -> 3.6473139 | V31: =(H31*P31+I31*Q31+J31*R31+K31*S31)/(P31+Q31+R31+S31) -> 3.5045444 | W31: =($U$32-T31)/($U$32) -> 0.28556815 | X31: =($U$32-U31)/($U$32) -> 0.072615845
A32: 0.67 | B32: 2 | C32: 2 | D32: 0.5 | E32: -0.15 | F32: 0 | G32: 0 | H32: 0 | I32: 4.053026 | J32: 0 | K32: 3.8087454 | L32: 0 | M32: 2.5592495 | N32: 0 | O32: 2.2687806 | P32: 0 | Q32: 15248 | R32: 0 | S32: 14752 | U32: =(I32*Q32+K32*S32)/(Q32+S32) -> 3.9329051
A33: 0.5 | B33: 2 | C33: 2 | D33: 0.5 | E33: -0.15 | F33: 0 | G33: 1 | H33: 2.4264203 | I33: 0 | J33: 2.4226525 | K33: 0 | L33: 0.82390855 | M33: 0 | N33: 0.81267409 | O33: 0 | P33: 15053 | Q33: 0 | R33: 14947 | S33: 0 | T33: =(H33*P33+J33*R33)/(P33+R33) -> 2.4245431 | V33: =(H33*P33+I33*Q33+J33*R33+K33*S33)/(P33+Q33+R33+S33) -> 2.4245431 | W33: =($U$39-T33)/($U$39) -> 0.19070977
A34: 0.5 | B34: 2 | C34: 2 | D34: 0.5 | E34: -0.15 | F34: 0 | G34: 0.83 | H34: 2.4175809 | I34: 2.7646736 | J34: 2.4146862 | K34: 2.7479881 | L34: 0.81575665 | M34: 1.0740898 | N34: 0.81838892 | O34: 1.0541538 | P34: 12517 | Q34: 2496 | R34: 12446 | S34: 2541 | T34: =(H34*P34+J34*R34)/(P34+R34) -> 2.4161376 | U34: =(I34*Q34+K34*S34)/(Q34+S34) -> 2.7562563 | V34: =(H34*P34+I34*Q34+J34*R34+K34*S34)/(P34+Q34+R34+S34) -> 2.4732436 | W34: =($U$39-T34)/($U$39) -> 0.19351543 | X34: =($U$39-U34)/($U$39) -> 0.07998693
A35: 0.5 | B35: 2 | C35: 2 | D35: 0.5 | E35: -0.15 | F35: 0 | G35: 0.67 | H35: 2.4009932 | I35: 2.7399852 | J35: 2.4150458 | K35: 2.797239 | L35: 0.79879004 | M35: 1.0652833 | N35: 0.81959913 | O35: 1.1142148 | P35: 10010 | Q35: 4925 | R35: 10088 | S35: 4977 | T35: =(H35*P35+J35*R35)/(P35+R35) -> 2.4080467 | U35: =(I35*Q35+K35*S35)/(Q35+S35) -> 2.7687624 | V35: =(H35*P35+I35*Q35+J35*R35+K35*S35)/(P35+Q35+R35+S35) -> 2.527107 | W35: =($U$39-T35)/($U$39) -> 0.1962161 | X35: =($U$39-U35)/($U$39) -> 0.075812504
A36: 0.5 | B36: 2 | C36: 2 | D36: 0.5 | E36: -0.15 | F36: 0 | G36: 0.5 | H36: 2.3907562 | I36: 2.7771487 | J36: 2.3910381 | K36: 2.8191506 | L36: 0.78655358 | M36: 1.1169052 | N36: 0.79158262 | O36: 1.1604049 | P36: 7595 | Q36: 7368 | R36: 7594 | S36: 7443 | T36: =(H36*P36+J36*R36)/(P36+R36) -> 2.3908972 | U36: =(I36*Q36+K36*S36)/(Q36+S36) -> 2.798256 | V36: =(H36*P36+I36*Q36+J36*R36+K36*S36)/(P36+Q36+R36+S36) -> 2.5920102 | W36: =($U$39-T36)/($U$39) -> 0.20194047 | X36: =($U$39-U36)/($U$39) -> 0.065967824
A37: 0.5 | B37: 2 | C37: 2 | D37: 0.5 | E37: -0.15 | F37: 0 | G37: 0.33 | H37: 2.3963168 | I37: 2.8657032 | J37: 2.3675229 | K37: 2.8644271 | L37: 0.8067439 | M37: 1.2310727 | N37: 0.76202924 | O37: 1.2484459 | P37: 5015 | Q37: 10062 | R37: 4860 | S37: 10063 | T37: =(H37*P37+J37*R37)/(P37+R37) -> 2.3821458 | U37: =(I37*Q37+K37*S37)/(Q37+S37) -> 2.8650651 | V37: =(H37*P37+I37*Q37+J37*R37+K37*S37)/(P37+Q37+R37+S37) -> 2.7061042 | W37: =($U$39-T37)/($U$39) -> 0.20486158 | X37: =($U$39-U37)/($U$39) -> 0.043667552
A38: 0.5 | B38: 2 | C38: 2 | D38: 0.5 | E38: -0.15 | F38: 0 | G38: 0.17 | H38: 2.3706272 | I38: 2.9034392 | J38: 2.3724021 | K38: 2.8473037 | L38: 0.75412705 | M38: 1.369245 | N38: 0.78305948 | O38: 1.2551017 | P38: 2568 | Q38: 12498 | R38: 2553 | S38: 12381 | T38: =(H38*P38+J38*R38)/(P38+R38) -> 2.371512 | U38: =(I38*Q38+K38*S38)/(Q38+S38) -> 2.8755035 | V38: =(H38*P38+I38*Q38+J38*R38+K38*S38)/(P38+Q38+R38+S38) -> 2.7894721 | W38: =($U$39-T38)/($U$39) -> 0.20841104 | X38: =($U$39-U38)/($U$39) -> 0.040183328
A39: 0.5 | B39: 2 | C39: 2 | D39: 0.5 | E39: -0.15 | F39: 0 | G39: 0 | H39: 0 | I39: 2.9771219 | J39: 0 | K39: 3.0144803 | L39: 0 | M39: 1.5298791 | N39: 0 | O39: 1.5480581 | P39: 0 | Q39: 14930 | R39: 0 | S39: 15070 | U39: =(I39*Q39+K39*S39)/(Q39+S39) -> 2.9958882
A40: 1.05 | B40: 2 | C40: 2 | D40: 0.5 | E40: -0.15 | F40: 0 | G40: 1 | H40: 31.632206 | I40: 0 | J40: 31.646424 | K40: 0 | L40: 16.62119 | M40: 0 | N40: 16.602375 | O40: 0 | P40: 15012 | Q40: 0 | R40: 14988 | S40: 0 | T40: =(H40*P40+J40*R40)/(P40+R40) -> 31.63931 | V40: =(H40*P40+I40*Q40+J40*R40+K40*S40)/(P40+Q40+R40+S40) -> 31.63931 | W40: =($U$46-T40)/($U$46) -> 0.15549766
A41: 1.05 | B41: 2 | C41: 2 | D41: 0.5 | E41: -0.15 | F41: 0 | G41: 0.83 | H41: 37.580045 | I41: 37.962618 | J41: 37.474904 | K41: 38.113741 | L41: 19.129896 | M41: 19.780879 | N41: 19.189592 | O41: 18.848378 | P41: 12431 | Q41: 2560 | R41: 12485 | S41: 2524 | T41: =(H41*P41+J41*R41)/(P41+R41) -> 37.527361 | U41: =(I41*Q41+K41*S41)/(Q41+S41) -> 38.037644 | V41: =(H41*P41+I41*Q41+J41*R41+K41*S41)/(P41+Q41+R41+S41) -> 37.613837 | W41: =($U$46-T41)/($U$46) -> -0.001663568 | X41: =($U$46-U41)/($U$46) -> -0.015283835
...

Sheet Chart1

Sheet Sheet3
A1: Time | B1: Arrived | C1: Departed | D1: Time | E1: CumArrival | F1: CumDeparture | G1: Time | H1: DifferencedCumArrivals | I1: DifferencedCumDeparture
A2: 5 | B2: 6 | C2: 3 | D2: 5 | E2: =B2 -> 6 | F2: =C2 -> 3 | G2: =D2 -> 5 | H2: =E2-D2*0.95 -> 1.25 | I2: =F2-D2*0.95 -> -1.75
A3: 10 | B3: 8 | C3: 3 | D3: 10 | E3: =B3+E2 -> 14 | F3: =C3+F2 -> 6 | G3: =D3 -> 10 | H3: =E3-D3*0.95 -> 4.5 | I3: =F3-D3*0.95 -> -3.5
A4: 15 | B4: 7 | C4: 6 | D4: 15 | E4: =B4+E3 -> 21 | F4: =C4+F3 -> 12 | G4: =D4 -> 15 | H4: =E4-D4*0.95 -> 6.75 | I4: =F4-D4*0.95 -> -2.25
A5: 20 | B5: 4 | C5: 5 | D5: 20 | E5: =B5+E4 -> 25 | F5: =C5+F4 -> 17 | G5: =D5 -> 20 | H5: =E5-D5*0.95 -> 6 | I5: =F5-D5*0.95 -> -2
A6: 25 | B6: 7 | C6: 5 | D6: 25 | E6: =B6+E5 -> 32 | F6: =C6+F5 -> 22 | G6: =D6 -> 25 | H6: =E6-D6*0.95 -> 8.25 | I6: =F6-D6*0.95 -> -1.75
A7: 30 | B7: 10 | C7: 4 | D7: 30 | E7: =B7+E6 -> 42 | F7: =C7+F6 -> 26 | G7: =D7 -> 30 | H7: =E7-D7*0.95 -> 13.5 | I7: =F7-D7*0.95 -> -2.5
A8: 35 | B8: 6 | C8: 6 | D8: 35 | E8: =B8+E7 -> 48 | F8: =C8+F7 -> 32 | G8: =D8 -> 35 | H8: =E8-D8*0.95 -> 14.75 | I8: =F8-D8*0.95 -> -1.25
A9: 40 | B9: 6 | C9: 4 | D9: 40 | E9: =B9+E8 -> 54 | F9: =C9+F8 -> 36 | G9: =D9 -> 40 | H9: =E9-D9*0.95 -> 16 | I9: =F9-D9*0.95 -> -2
A10: 45 | B10: 4 | C10: 6 | D10: 45 | E10: =B10+E9 -> 58 | F10: =C10+F9 -> 42 | G10: =D10 -> 45 | H10: =E10-D10*0.95 -> 15.25 | I10: =F10-D10*0.95 -> -0.75
A11: 50 | B11: 9 | C11: 4 | D11: 50 | E11: =B11+E10 -> 67 | F11: =C11+F10 -> 46 | G11: =D11 -> 50 | H11: =E11-D11*0.95 -> 19.5 | I11: =F11-D11*0.95 -> -1.5
A12: 55 | B12: 3 | C12: 6 | D12: 55 | E12: =B12+E11 -> 70 | F12: =C12+F11 -> 52 | G12: =D12 -> 55 | H12: =E12-D12*0.95 -> 17.75 | I12: =F12-D12*0.95 -> -0.25
A13: 60 | B13: 5 | C13: 4 | D13: 60 | E13: =B13+E12 -> 75 | F13: =C13+F12 -> 56 | G13: =D13 -> 60 | H13: =E13-D13*0.95 -> 18 | I13: =F13-D13*0.95 -> -1
A14: 65 | B14: 4 | C14: 5 | D14: 65 | E14: =B14+E13 -> 79 | F14: =C14+F13 -> 61 | G14: =D14 -> 65 | H14: =E14-D14*0.95 -> 17.25 | I14: =F14-D14*0.95 -> -0.75
... A203: 1010 | B203: 6 | C203: 5 | D203: 1010 | E203: =B203+E202 -> 954 | F203: =C203+F202 -> 939 | G203: =D203 -> 1010 | H203: =E203-D203*0.95 -> -5.5 | I203: =F203-D203*0.95 -> -20.5
A204: More | B204: 46 | C204: 61 | D204: More | E204: =B204+E203 -> 1000 | F204: =C204+F203 -> 1000
H241: =E241-D241 -> 0 | I241: =F241-D241 -> 0
H242: =E242-D242 -> 0 | I242: =F242-D242 -> 0
H243: =E243-D243 -> 0 | I243: =F243-D243 -> 0
H244: =E244-D244 -> 0 | I244: =F244-D244 -> 0
H245: =E245-D245 -> 0 | I245: =F245-D245 -> 0
H246: =E246-D246 -> 0 | I246: =F246-D246 -> 0
H247: =E247-D247 -> 0 | I247: =F247-D247 -> 0
H248: =E248-D248 -> 0 | I248: =F248-D248 -> 0
H249: =E249-D249 -> 0 | I249: =F249-D249 -> 0
H250: =E250-D250 -> 0 | I250: =F250-D250 -> 0
H251: =E251-D251 -> 0 | I251: =F251-D251 -> 0
H252: =E252-D252 -> 0 | I252: =F252-D252 -> 0
... H1091: =E1091-D1091 -> 0 | I1091: =F1091-D1091 -> 0

Sheet Sheet4
A1: Time | B1: Frequency | C1: Cumulative %
A2: 5 | B2: 3 | C2: 0.003
A3: 10 | B3: 3 | C3: 0.006
A4: 15 | B4: 6 | C4: 0.012
A5: 20 | B5: 5 | C5: 0.017
A6: 25 | B6: 5 | C6: 0.022
A7: 30 | B7: 4 | C7: 0.026
A8: 35 | B8: 6 | C8: 0.032
A9: 40 | B9: 4 | C9: 0.036
A10: 45 | B10: 6 | C10: 0.042
A11: 50 | B11: 4 | C11: 0.046
A12: 55 | B12: 6 | C12: 0.052
A13: 60 | B13: 4 | C13: 0.056
... A203: 1010 | B203: 5 | C203: 0.939
A204: More | B204: 61 | C204: 1

Sheet Sheet1
A1: THE VALUE OF INFORMATION: QUEUEING MODEL
A2: Poisson arrival rate (cust/sec) = | B2: 0.95
A3: Freeway Service time mean (sec) = | B3: 2
A4: Arterial Service time mean (sec) = | B4: 2
A5: Freeway Service time range (sec) = | B5: 0.5
A6: Demand Coefficient = | B6: -0.15
A7: Alternate Time (sec) | B7: 0
A8: Percent Informed | B8: 0.5
A10: Percent Arterial (RESULT) | B10: 0.504
A11: Percent Informed (RESULT) | B11: 0.489
A15: CUSTOMER | B15: ARRIVAL | C15: DEPARTURE
A16: # | B16: TIME | C16: TIME
A17: CUSTOMER | B17: ARRIVAL | C17: DEPARTURE | F17: Time
A18: 1 | B18: 0 | C18: 1.9305107 | F18: 5
A19: 2 | B19: 0.26618856 | C19: 2.3743889 | F19: =5+F18 -> 10
A20: 3 | B20: 0.46975435 | C20: 4.6153219 | F20: =5+F19 -> 15
A21: 4 | B21: 1.6968987 | C21: 6.4244978 | F21: =5+F20 -> 20
A22: 5 | B22: 3.4259661 | C22: 8.4468813 | F22: =5+F21 -> 25
A23: 6 | B23: 4.639081 | C23: 10.380318 | F23: =5+F22 -> 30
A24: 7 | B24: 6.0434611 | C24: 8.1951812 | F24: =5+F23 -> 35
A25: 8 | B25: 6.2061803 | C25: 10.343948 | F25: =5+F24 -> 40
A26: 9 | B26: 6.7974224 | C26: 12.272011 | F26: =5+F25 -> 45
A27: 10 | B27: 7.2681451 | C27: 14.19028 | F27: =5+F26 -> 50
A28: 11 | B28: 7.2681982 | C28: 12.321331 | F28: =5+F27 -> 55
A29: 12 | B29: 8.114514 | C29: 15.972636 | F29: =5+F28 -> 60
A30: 13 | B30: 8.7416156 | C30: 14.438621 | F30: =5+F29 -> 65
... A219: 202 | B219: 213.16997 | C219: 215.90764 | F219: =5+F218 -> 1010
A220: 203 | B220: 214.7728 | C220: 218.02356
A221: 204 | B221: 214.90736 | C221: 220.41966
A222: 205 | B222: 215.34269 | C222: 220.14963
A223: 206 | B223: 215.67761 | C223: 222.16739
A224: 207 | B224: 216.52654 | C224: 222.56881
A225: 208 | B225: 217.25166 | C225: 224.27323
A226: 209 | B226: 217.50279 | C226: 224.81466
A227: 210 | B227: 217.52557 | C227: 226.90012
A228: 211 | B228: 217.57152 | C228: 226.4759
A229: 212 | B229: 218.59124 | C229: 229.06679
A230: 213 | B230: 219.476 | C230: 228.61209
A231: 214 | B231: 220.10901 | C231: 231.30958
... A1017: 1000 | B1017: 1052.7718 | C1017: 1073.5018
...

Sheet Chart2

Sheet HistoQ
A1: -1 | B1: 0.95 | C1: Cumulative % | E1: -1 | F1: 1.05 | G1: Cumulative %
A2: 0 | B2: 357 | C2: 0.357 | E2: 0 | F2: 309 | G2: 0.309
A3: 1 | B3: 430 | C3: 0.787 | E3: 1 | F3: 454 | G3: 0.763
A4: 2 | B4: 144 | C4: 0.931 | E4: 2 | F4: 187 | G4: 0.95
A5: 3 | B5: 57 | C5: 0.988 | E5: 3 | F5: 42 | G5: 0.992
A6: 4 | B6: 7 | C6: 0.995 | E6: 4 | F6: 8 | G6: 1
A7: 5 | B7: 5 | C7: 1 | E7: 5 | F7: 0 | G7: 1
A8: More | B8: 0 | C8: 1 | E8: More | F8: 0 | G8: 1

Sheet Sheet5
A1: THE VALUE OF INFORMATION: QUEUEING MODEL | F1: RESET (1=Y,0=N) | G1: 0
A2: Poisson arrival rate (cust/sec) = | D2: 0.95 | F2: ITERATION | G2: 48
A3: Freeway Service time mean (sec) = | D3: 2
A4: Arterial Service time mean (sec) = | D4: 2
A5: Freeway Service time range (sec) = | D5: 0.5
A6: Demand Coefficient = | D6: -0.15
A7: Alternate Time (sec) | D7: 0
A8: Percent Informed | D8: 0.5
A10: Percent Arterial (RESULT) | D10: 0.497
A11: Percent Informed (RESULT) | D11: 0.495
E14: EXPECTED | F14: EXPECTED | G14: ART. | I14: FREEWAY | J14: FREEWAY | K14: FREEWAY | L14: ARTERIAL | M14: ARTERIAL | N14: ARTERIAL | R14: CUMULATIVE | S14: CUMULATIVE | T14: CUMULATIVE | U14: CUMULATIVE | V14: AVERAGE | W14: AVERAGE | X14: INFORMED | Y14: UNINFORMED | Z14: INFORMED | AA14: UNINFORMED | AB14: INFORMED | AC14: UNINFORMED | AD14: INFORMED | AE14: UNINFORMED | AF14: (X-E(X))^2 | AG14: (X-E(X))^2 | AH14: (X-E(X))^2 | AI14: (X-E(X))^2
A15: CUSTOMER | B15: (1=Y,0=N) | C15: ARRIVAL | D15: ARRIVAL | E15: FREEWAY | F15: ARTERIAL | G15: Uninform | H15: F/A | I15: SERVICE | J15: DEPARTURE | K15: DELAY | L15: SERVICE | M15: DEPARTURE | N15: DELAY | O15: CUSTOMER | P15: Freeway | Q15: Arterial | R15: ACTUAL | S15: ACTUAL | T15: ACTUAL | U15: ACTUAL | V15: FREEWAY | W15: ARTERIAL | X15: FREEWAY | Y15: FREEWAY | Z15: ARTERIAL | AA15: ARTERIAL | AB15: FREEWAY | AC15: FREEWAY | AD15: ARTERIAL | AE15: ARTERIAL | AF15: FREEWAY | AG15: FREEWAY | AH15: ARTERIAL | AI15: ARTERIAL | AO15: CUSTOMER | AP15: (1=Y,0=N) | AQ15: ARRIVAL | AR15: ARRIVAL | AS15: FREEWAY | AT15: ARTERIAL
A16: # | C16: HEADWAY | D16: TIME | E16: DELAY | F16: DELAY | G16: SPLIT | H16: F=0,A=1 | I16: TIME | J16: TIME | K16: TIME | L16: TIME | M16: TIME | N16: TIME | O16: # | P16: # | Q16: # | R16: FWY DELAY | S16: ART DELAY | T16: FWY USERS | U16: ART USERS | V16: DELAY | W16: DELAY | X16: DELAY | Y16: DELAY | Z16: DELAY | AA16: DELAY | AB16: USERS | AC16: USERS | AD16: USERS | AE16: USERS | AF16: INFORMED | AG16: UNINFORMED | AH16: INFORMED | AI16: UNINFORMED | AO16: # | AQ16: HEADWAY | AR16: TIME | AS16: DELAY | AT16: DELAY
B17: Informed | H17: Arterial | AJ17: -1 | AK17: Cust# | AL17: V/C 0.95 | AM17: V/C 1.05 | AP17: Informed
A18: 1 | B18: 1 | C18: 0 | D18: 0 | E18: 0 | F18: 0 | G18: 0.5 | H18: 0 | I18: 1.845117 | J18: 1.845117 | K18: 1.845117 | L18: 0 | M18: 0 | N18: 0 | O18: 1 | P18: 1 | Q18: 0 | R18: 95.334505 | S18: 0 | T18: 48 | U18: 0 | V18: 1.9861351 | W18: 0 | X18: 1.845117 | Y18: 0 | Z18: 0 | AA18: 0 | AB18: 1 | AC18: 0 | AD18: 0 | AE18: 0 | AF18: 31.163672 | AG18: 0 | AH18: 0 | AI18: 0 | AJ18: 0 | AK18: =A18 -> 1 | AL18: 0 | AM18: 0 | AO18: 1 | AP18: 0 | AQ18: 0 | AR18: 0 | AS18: 0 | AT18: 0
A19: 2 | B19: 1 | C19: 1.4829259 | D19: 1.4829259 | E19: 0 | F19: 0 | G19: 0.5 | H19: 1 | I19: 0 | J19: 1.845117 | K19: 0 | L19: 2.216811 | M19: 3.6997368 | N19: 2.216811 | O19: 2 | P19: 1 | Q19: 1 | R19: 63.607255 | S19: 53.740603 | T19: 22 | U19: 26 | V19: 2.8912376 | W19: 2.0669383 | X19: 0 | Y19: 0 | Z19: 2.216811 | AA19: 0 | AB19: 0 | AC19: 0 | AD19: 1 | AE19: 0 | AF19: 0 | AG19: 0 | AH19: 30.792425 | AI19: 0 | AJ19: 1 | AK19: =A19 -> 2 | AL19: 0 | AM19: 0 | AO19: 2 | AP19: 1 | AQ19: 0.61297443 | AR19: 0.61297443 | AS19: 0 | AT19: 0
A20: 3 | B20: 1 | C20: 0.14588263 | D20: 1.6288085 | E20: 0 | F20: 0 | G20: 0.5 | H20: 0 | I20: 1.9994921 | J20: 3.8446091 | K20: 2.2158006 | L20: 0 | M20: 3.6997368 | N20: 0 | O20: 3 | P20: 2 | Q20: 1 | R20: 74.092304 | S20: 63.621736 | T20: 25 | U20: 23 | V20: 2.963691 | W20: 2.7661504 | X20: 2.2158006 | Y20: 0 | Z20: 0 | AA20: 0 | AB20: 1 | AC20: 0 | AD20: 0 | AE20: 0 | AF20: 27.162437 | AG20: 0 | AH20: 0 | AI20: 0 | AJ20: 2 | AK20: =A20 -> 3 | AL20: 0 | AM20: 0 | AO20: 3 | AP20: 1 | AQ20: 3.654585 | AR20: 4.2675594 | AS20: 0 | AT20: 0
A21: 4 | B21: 0 | C21: 1.5091871 | D21: 3.1379956 | E21: 0 | F21: 0 | G21: 0.5 | H21: 1 | I21: 0 | J21: 3.8446091 | K21: 0 | L21: 1.9064564 | M21: 5.6061933 | N21: 2.4681977 | O21: 4 | P21: 2 | Q21: 2 | R21: 71.929209 | S21: 89.129638 | T21: 21 | U21: 27 | V21: 3.4251988 | W21: 3.3010855 | X21: 0 | Y21: 0 | Z21: 0 | AA21: 2.4681977 | AB21: 0 | AC21: 0 | AD21: 0 | AE21: 1 | AF21: 0 | AG21: 0 | AH21: 0 | AI21: 27.701307 | AJ21: 3 | AK21: =A21 -> 4 | AL21: 0 | AM21: 0 | AO21: 4 | AP21: 1 | AQ21: 0.13517795 | AR21: 4.4027374 | AS21: 0 | AT21: 0
A22: 5 | B22: 1 | C22: 0.3466343 | D22: 3.4846299 | E22: 0 | F22: 0 | G22: 0.5 | H22: 0 | I22: 2.1179476 | J22: 5.9625567 | K22: 2.4779268 | L22: 0 | M22: 5.6061933 | N22: 0 | O22: 5 | P22: 3 | Q22: 2 | R22: 95.045995 | S22: 75.913458 | T22: 25 | U22: 23 | V22: 3.8018383 | W22: 3.3005708 | X22: 2.4779268 | Y22: 0 | Z22: 0 | AA22: 0 | AB22: 1 | AC22: 0 | AD22: 0 | AE22: 0 | AF22: 24.49887 | AG22: 0 | AH22: 0 | AI22: 0 | AJ22: 4 | AK22: =A22 -> 5 | AL22: 0 | AM22: 0 | AO22: 5 | AP22: 1 | AQ22: 0.39893849 | AR22: 4.8016759 | AS22: 0 | AT22: 0
A23: 6 | B23: 1 | C23: 0.39495618 | D23: 3.8795861 | E23: 0 | F23: 0 | G23: 0.5 | H23: 1 | I23: 0 | J23: 5.9625567 | K23: 0 | L23: 1.9140453 | M23: 7.5202385 | N23: 3.6406525 | O23: 6 | P23: 3 | Q23: 3 | R23: 75.614709 | S23: 102.70228 | T23: 21 | U23: 27 | V23: 3.6006987 | W23: 3.8037741 | X23: 0 | Y23: 0 | Z23: 3.6406525 | AA23: 0 | AB23: 0 | AC23: 0 | AD23: 1 | AE23: 0 | AF23: 0 | AG23: 0 | AH23: 17.017694 | AI23: 0 | AJ23: 5 | AK23: =A23 -> 6 | AL23: 0 | AM23: 0 | AO23: 6 | AP23: 1 | AQ23: 1.2669648 | AR23: 6.0686407 | AS23: 0 | AT23: 0
A24: 7 | B24: 1 | C24: 0.41688712 | D24: 4.2964732 | E24: 0 | F24: 0 | G24: 0.5 | H24: 0 | I24: 1.9690829 | J24: 7.9316396 | K24: 3.6351665 | L24: 0 | M24: 7.5202385 | N24: 0 | O24: 7 | P24: 4 | Q24: 3 | R24: 118.96899 | S24: 97.106672 | T24: 26 | U24: 22 | V24: 4.5757284 | W24: 4.4139196 | X24: 3.6351665 | Y24: 0 | Z24: 0 | AA24: 0 | AB24: 1 | AC24: 0 | AD24: 0 | AE24: 0 | AF24: 14.38225 | AG24: 0 | AH24: 0 | AI24: 0 | AK24: =A24 -> 7 | AL24: 0 | AM24: 0 | AO24: 7 | AP24: 0 | AQ24: 0.1780396 | AR24: 6.2466803 | AS24: 0 | AT24: 0
A25: 8 | B25: 1 | C25: 0.67343979 | D25: 4.969913 | E25: 0 | F25: 0 | G25: 0.5 | H25: 0 | I25: 1.9690992 | J25: 9.9007388 | K25: 4.9308258 | L25: 0 | M25: 7.5202385 | N25: 0 | O25: 8 | P25: 5 | Q25: 3 | R25: 92.892667 | S25: 117.56176 | T25: 22 | U25: 26 | V25: 4.222392 | W25: 4.5215887 | X25: 4.9308258 | Y25: 0 | Z25: 0 | AA25: 0 | AB25: 1 | AC25: 0 | AD25: 0 | AE25: 0 | AF25: 6.2336822 | AG25: 0 | AH25: 0 | AI25: 0 | AK25: =A25 -> 8 | AL25: 0 | AM25: 0 | AO25: 8 | AP25: 0 | AQ25: 0.40421737 | AR25: 6.6508977 | AS25: 0 | AT25: 0
A26: 9 | B26: 1 | C26: 0.05087731 | D26: 5.0207903 | E26: 0 | F26: 0 | G26: 0.5 | H26: 1 | I26: 0 | J26: 9.9007388 | K26: 0 | L26: 1.9443406 | M26: 9.4645792 | N26: 4.4437889 | O26: 9 | P26: 5 | Q26: 4 | R26: 116.15577 | S26: 108.15796 | T26: 25 | U26: 23 | V26: 4.6462288 | W26: 4.7024994 | X26: 0 | Y26: 0 | Z26: 4.4437889 | AA26: 0 | AB26: 0 | AC26: 0 | AD26: 1 | AE26: 0 | AF26: 0 | AG26: 0 | AH26: 11.036444 | AI26: 0 | AK26: =A26 -> 9 | AL26: 0 | AM26: 0 | AO26: 9 | AP26: 0 | AQ26: 0.55816788 | AR26: 7.2090656 | AS26: 0 | AT26: 0
A27: 10 | B27: 0 | C27: 0.21212599 | D27: 5.2329163 | E27: 0 | F27: 0 | G27: 0.5 | H27: 1 | I27: 0 | J27: 9.9007388 | K27: 0 | L27: 1.9749251 | M27: 11.439504 | N27: 6.206588 | O27: 10 | P27: 5 | Q27: 5 | R27: 129.91736 | S27: 101.83641 | T27: 25 | U27: 23 | V27: 5.1966922 | W27: 4.4276509 | X27: 0 | Y27: 0 | Z27: 0 | AA27: 6.206588 | AB27: 0 | AC27: 0 | AD27: 0 | AE27: 1 | AF27: 0 | AG27: 0 | AH27: 0 | AI27: 2.325054 | AK27: =A27 -> 10 | AL27: 0 | AM27: 0 | AO27: 10 | AP27: 1 | AQ27: 0.39212675 | AR27: 7.6011923 | AS27: 0 | AT27: 0
A28: 11 | B28: 0 | C28: 0.29457091 | D28: 5.5274872 | E28: 8 | F28: 10 | G28: 0.5 | H28: 0 | I28: 2.0463521 | J28: 11.947091 | K28: 6.4196038 | L28: 0 | M28: 11.439504 | N28: 0 | O28: 11 | P28: 6 | Q28: 5 | R28: 69.022379 | S28: 112.37351 | T28: 20 | U28: 28 | V28: 3.4511172 | W28: 4.0133252 | X28: 0 | Y28: 6.4196038 | Z28: 0 | AA28: 0 | AB28: 0 | AC28: 1 | AD28: 0 | AE28: 0 | AF28: 0 | AG28: 3.382117 | AH28: 0 | AI28: 0 | AK28: =A28 -> 11 | AL28: 1 | AM28: 4 | AO28: 11 | AP28: 0 | AQ28: 0.43327537 | AR28: 8.0344677 | AS28: 4 | AT28: 12
A29: 12 | B29: 0 | C29: 1.1167679 | D29: 6.6442551 | E29: 8 | F29: 8 | G29: 0.5 | H29: 1 | I29: 0 | J29: 11.947091 | K29: 0 | L29: 2.1259579 | M29: 13.565462 | N29: 6.9212071 | O29: 12 | P29: 6 | Q29: 6 | R29: 95.585472 | S29: 116.84322 | T29: 24 | U29: 24 | V29: 3.9827264 | W29: 4.8684472 | X29: 0 | Y29: 0 | Z29: 0 | AA29: 6.9212071 | AB29: 0 | AC29: 0 | AD29: 0 | AE29: 1 | AF29: 0 | AG29: 0 | AH29: 0 | AI29: 0.65641377 | AK29: =A29 -> 12 | AL29: 0 | AM29: 4 | AO29: 12 | AP29: 1 | AQ29: 1.2158863 | AR29: 9.250354 | AS29: 4 | AT29: 12
A30: 13 | B30: 1 | C30: 0.070069295 | D30: 6.7143244 | E30: 8 | F30: 10 | G30: 0.5 | H30: 0 | I30: 1.8367126 | J30: 13.783804 | K30: 7.0694792 | L30: 0 | M30: 13.565462 | N30: 0 | O30: 13 | P30: 7 | Q30: 6 | R30: 105.67936 | S30: 114.87799 | T30: 23 | U30: 25 | V30: 4.5947527 | W30: 4.5951013 | X30: 7.0694792 | Y30: 0 | Z30: 0 | AA30: 0 | AB30: 1 | AC30: 0 | AD30: 0 | AE30: 0 | AF30: 0.12822197 | AG30: 0 | AH30: 0 | AI30: 0 | AK30: =A30 -> 13 | AL30: 1 | AM30: 4 | AO30: 13 | AP30: 1 | AQ30: 0.73208892 | AR30: 9.9824429 | AS30: 4 | AT30: 12
A31: 14 | B31: 0 | C31: 1.1916484 | D31: 7.9059727 | E31: 10 | F31: 8 | G31: 0.5 | H31: 1 | I31: 0 | J31: 13.783804 | K31: 0 | L31: 1.8736117 | M31: 15.439074 | N31: 7.5331011 | O31: 14 | P31: 7 | Q31: 7 | R31: 124.78477 | S31: 103.36954 | T31: 26 | U31: 22 | V31: 4.7994124 | W31: 4.6985942 | X31: 0 | Y31: 0 | Z31: 0 | AA31: 7.5331011 | AB31: 0 | AC31: 0 | AD31: 0 | AE31: 1 | AF31: 0 | AG31: 0 | AH31: 0 | AI31: 0.039322753 | AK31: =A31 -> 14 | AL31: 1 | AM31: 2 | AO31: 14 | AP31: 1 | AQ31: 1.3484183 | AR31: 11.330861 | AS31: 6 | AT31: 10
A32: 15 | B32: 1 | C32: 0.46984358 | D32: 8.3758163 | E32: 8 | F32: 10 | G32: 0.5 | H32: 0 | I32: 1.826102 | J32: 15.609906 | K32: 7.2340892 | L32: 0 | M32: 15.439074 | N32: 0 | O32: 15 | P32: 8 | Q32: 7 | R32: 139.76188 | S32: 116.12059 | T32: 27 | U32: 21 | V32: 5.176364 | W32: 5.5295257 | X32: 7.2340892 | Y32: 0 | Z32: 0 | AA32: 0 | AB32: 1 | AC32: 0 | AD32: 0 | AE32: 0 | AF32: 0.037430996 | AG32: 0 | AH32: 0 | AI32: 0 | AK32: =A32 -> 15 | AL32: 1 | AM32: 2 | AO32: 15 | AP32: 1 | AQ32: 0.59986394 | AR32: 11.930725 | AS32: 6 | AT32: 10
A33: 16 | B33: 1 | C33: 0.9223547 | D33: 9.298171 | E33: 10 | F33: 10 | G33: 0.5 | H33: 1 | I33: 0 | J33: 15.609906 | K33: 0 | L33: 2.0902499 | M33: 17.529324 | N33: 8.2311528 | O33: 16 | P33: 8 | Q33: 8 | R33: 128.67318 | S33: 125.07245 | T33: 24 | U33: 24 | V33: 5.3613802 | W33: 5.2113305 | X33: 0 | Y33: 0 | Z33: 8.2311528 | AA33: 0 | AB33: 0 | AC33: 0 | AD33: 1 | AE33: 0 | AF33: 0 | AG33: 0 | AH33: 0.21645707 | AI33: 0 | AK33: =A33 -> 16 | AL33: 0 | AM33: 1 | AO33: 16 | AP33: 1 | AQ33: 0.35125515 | AR33: 12.28198 | AS33: 8 | AT33: 10
A34: 17 | B34: 0 | C34: 1.3230324 | D34: 10.621203 | E34: 8 | F34: 10 | G34: 0.5 | H34: 1 | I34: 0 | J34: 15.609906 | K34: 0 | L34: 2.1183654 | M34: 19.647689 | N34: 9.0264857 | O34: 17 | P34: 8 | Q34: 9 | R34: 98.803172 | S34: 160.91798 | T34: 17 | U34: 31 | V34: 5.8119479 | W34: 5.1908859 | X34: 0 | Y34: 0 | Z34: 0 | AA34: 9.0264857 | AB34: 0 | AC34: 0 | AD34: 0 | AE34: 1 | AF34: 0 | AG34: 0 | AH34: 0 | AI34: 1.6772451 | AK34: =A34 -> 17 | AL34: 1 | AM34: 0 | AO34: 17 | AP34: 1 | AQ34: 0.35318657 | AR34: 12.635167 | AS34: 10 | AT34: 10
A35: 18 | B35: 0 | C35: 0.1604491 | D35: 10.781653 | E35: 8 | F35: 12 | G35: 0.5 | H35: 0 | I35: 1.8329022 | J35: 17.442808 | K35: 6.6611552 | L35: 0 | M35: 19.647689 | N35: 0 | O35: 18 | P35: 9 | Q35: 9 | R35: 131.72228 | S35: 130.6827 | T35: 25 | U35: 23 | V35: 5.2688893 | W35: 5.6818317 | X35: 0 | Y35: 6.6611552 | Z35: 0 | AA35: 0 | AB35: 0 | AC35: 1 | AD35: 0 | AE35: 0 | AF35: 0 | AG35: 2.552012 | AH35: 0 | AI35: 0 | AK35: =A35 -> 18 | AL35: 2 | AM35: 2 | AO35: 18 | AP35: 0 | AQ35: 0.6298199 | AR35: 13.264987 | AS35: 12 | AT35: 8
... A1017: 1000 | B1017: 0 | C1017: 0.53479675 | D1017: 1085.4564 | E1017: 6 | F1017: 2 | G1017: 0.5 | H1017: 0 | I1017: 1.9438294 | J1017: 1089.9964 | K1017: 4.5400293 | L1017: 0 | M1017: 1085.4564 | N1017: 0 | O1017: 1000 | P1017: 503 | Q1017: 497 | R1017: 821.74594 | S1017: 1233.656 | T1017: 23 | U1017: 25 | V1017: 35.728069 | W1017: 49.346041 | X1017: 0 | Y1017: 4.5400293 | Z1017: 0 | AA1017: 0 | AB1017: 0 | AC1017: 1 | AD1017: 0 | AE1017: 0 | AF1017: 0 | AG1017: 13.828192 | AH1017: 0 | AI1017: 0 | AK1017: =A1017 -> 1000 | AL1017: 2 | AM1017: 1 | AO1017: 1000 | AP1017: 0 | AQ1017: 0.083935953 | AR1017: 908.4527 | AS1017: 102 | AT1017: 100
AF1018: 0 | AG1018: 0 | AH1018: 0 | AI1018: 0
A1019: SUMS | B1019: 495 | C1019: 1085.4564 | D1019: 539128.96 | E1019: 9168 | F1019: 9024 | G1019: 500 | H1019: 497 | I1019: 1008.6575 | J1019: 546472.73 | K1019: 3948.8236 | L1019: 991.97662 | M1019: 546248.18 | N1019: 3851.0628 | O1019: 500500 | P1019: 252585 | Q1019: 247915 | R1019: 608213.22 | S1019: 607666.77 | T1019: 24015 | U1019: 23985 | V1019: 25315.706 | W1019: 25299.761 | X1019: 1834.6074 | Y1019: 2114.2162 | Z1019: 1925.944 | AA1019: 1925.1188 | AB1019: 247 | AC1019: 256 | AD1019: 248 | AE1019: 249 | AF1019: 0 | AG1019: 0 | AH1019: 0 | AI1019: 0
A1020: AVERAGES | C1020: 1.0854564 | E1020: 18.22664 | F1020: 18.156942 | G1020: 0.5 | H1020: 0.497 | T1020: 24.015 | U1020: 23.985 | X1020: 7.4275601 | Y1020: 8.258657 | Z1020: 7.7659033 | AA1020: 7.7314008
T1021: 3.4311146 | U1021: 3.4311146
A1022: CUMULATIVE SUMS | B1022: 41536 | C1022: 47268.179 | D1022: 23581494 | E1022: 1283098 | F1022: 1282996 | G1022: 24000 | H1022: 23985 | I1022: 48037.092 | J1022: 24772722 | K1022: 608213.22 | L1022: 47980.728 | M1022: 24772347 | N1022: 607666.77 | O1022: 24024000 | P1022: 12022945 | Q1022: 12001055 | R1022: 17339783 | S1022: 17321885 | T1022: 588333 | U1022: 587667 | V1022: 1392069.2 | W1022: 1389517 | X1022: 580225.65 | Y1022: 27987.57 | Z1022: 580642.5 | AA1022: 27024.272 | AB1022: 20782 | AC1022: 3233 | AD1022: 20754 | AE1022: 3231
A1023: CUMULATIVE AVGS | X1023: 27.919625 | Y1023: 8.6568419 | Z1023: 27.977378 | AA1023: 8.3640582
